{
 "cells": [
  {
   "cell_type": "code",
   "execution_count": 4,
   "id": "4afaa5c1-a4bc-45af-91ba-7edea5aac7c7",
   "metadata": {},
   "outputs": [
    {
     "name": "stderr",
     "output_type": "stream",
     "text": [
      "WARNING: Retrying (Retry(total=4, connect=None, read=None, redirect=None, status=None)) after connection broken by 'NewConnectionError('<pip._vendor.urllib3.connection.HTTPSConnection object at 0x0000012C3CE9FDD0>: Failed to establish a new connection: [Errno 11001] getaddrinfo failed')': /simple/panda/\n",
      "WARNING: Retrying (Retry(total=3, connect=None, read=None, redirect=None, status=None)) after connection broken by 'NewConnectionError('<pip._vendor.urllib3.connection.HTTPSConnection object at 0x0000012C39C348D0>: Failed to establish a new connection: [Errno 11001] getaddrinfo failed')': /simple/panda/\n",
      "WARNING: Retrying (Retry(total=2, connect=None, read=None, redirect=None, status=None)) after connection broken by 'NewConnectionError('<pip._vendor.urllib3.connection.HTTPSConnection object at 0x0000012C3D0081D0>: Failed to establish a new connection: [Errno 11001] getaddrinfo failed')': /simple/panda/\n",
      "WARNING: Retrying (Retry(total=1, connect=None, read=None, redirect=None, status=None)) after connection broken by 'NewConnectionError('<pip._vendor.urllib3.connection.HTTPSConnection object at 0x0000012C3D008C10>: Failed to establish a new connection: [Errno 11001] getaddrinfo failed')': /simple/panda/\n",
      "WARNING: Retrying (Retry(total=0, connect=None, read=None, redirect=None, status=None)) after connection broken by 'NewConnectionError('<pip._vendor.urllib3.connection.HTTPSConnection object at 0x0000012C3D0096D0>: Failed to establish a new connection: [Errno 11001] getaddrinfo failed')': /simple/panda/\n",
      "ERROR: Could not find a version that satisfies the requirement panda (from versions: none)\n",
      "ERROR: No matching distribution found for panda\n",
      "\n",
      "[notice] A new release of pip is available: 24.0 -> 24.1.2\n",
      "[notice] To update, run: python.exe -m pip install --upgrade pip\n"
     ]
    }
   ],
   "source": [
    "!pip install pandas numpt scipy"
   ]
  },
  {
   "cell_type": "code",
   "execution_count": 3,
   "id": "ba65a45f-1324-47bb-a49c-6da2320d1201",
   "metadata": {},
   "outputs": [
    {
     "ename": "ModuleNotFoundError",
     "evalue": "No module named 'pandas'",
     "output_type": "error",
     "traceback": [
      "\u001b[1;31m---------------------------------------------------------------------------\u001b[0m",
      "\u001b[1;31mModuleNotFoundError\u001b[0m                       Traceback (most recent call last)",
      "Cell \u001b[1;32mIn[3], line 1\u001b[0m\n\u001b[1;32m----> 1\u001b[0m \u001b[38;5;28;01mimport\u001b[39;00m \u001b[38;5;21;01mpandas\u001b[39;00m \u001b[38;5;28;01mas\u001b[39;00m \u001b[38;5;21;01mpd\u001b[39;00m\n\u001b[0;32m      2\u001b[0m \u001b[38;5;28;01mimport\u001b[39;00m \u001b[38;5;21;01mnumpy\u001b[39;00m \u001b[38;5;28;01mas\u001b[39;00m \u001b[38;5;21;01mnp\u001b[39;00m\n\u001b[0;32m      3\u001b[0m \u001b[38;5;28;01mfrom\u001b[39;00m \u001b[38;5;21;01mscipy\u001b[39;00m \u001b[38;5;28;01mimport\u001b[39;00m stats\n",
      "\u001b[1;31mModuleNotFoundError\u001b[0m: No module named 'pandas'"
     ]
    }
   ],
   "source": [
    "import pandas as pd\n",
    "import numpy as np\n",
    "from scipy import stats\n"
   ]
  },
  {
   "cell_type": "code",
   "execution_count": null,
   "id": "43e9a270-f75d-4cb2-9928-a5d92fc9d6fa",
   "metadata": {},
   "outputs": [],
   "source": []
  }
 ],
 "metadata": {
  "kernelspec": {
   "display_name": "Python 3 (ipykernel)",
   "language": "python",
   "name": "python3"
  },
  "language_info": {
   "codemirror_mode": {
    "name": "ipython",
    "version": 3
   },
   "file_extension": ".py",
   "mimetype": "text/x-python",
   "name": "python",
   "nbconvert_exporter": "python",
   "pygments_lexer": "ipython3",
   "version": "3.11.8"
  }
 },
 "nbformat": 4,
 "nbformat_minor": 5
}
